Workbook

Sheet Mobile Friendly
A5: FRI | D5: Pool 1 - Main Pool - Scoreboard
A6: Game | B6: Div | C6: Time | D6: Dark vs Light | E6: Pool | F6: Winner
A7: 1 | B7: {=XLOOKUP(A7,'Master Schedule'!$A$10:$A$90,'Master Schedule'!$B$10:$B$90)} -> 18u Boys | C7: {=XLOOKUP(A7,'Master Schedule'!$A$10:$A$90,'Master Schedule'!$D$10:$D$90)} -> 0.64583333 | D7: {=CONCATENATE(XLOOKUP(A7,'Master Schedule'!$A$10:$A$90,'Master Schedule'!$C$10:$C$90)," vs ",(XLOOKUP(A7,'Master Schedule'!$A$10:$A$90,'Master Schedule'!$E$10:$E$90)))} -> Orlando Thunder vs Team Orlando Black | E7: 1 | F7: {=xlookup(A7,Game_Scores!A:A,Game_Scores!J:J)} -> No_score
A8: 2 | B8: {=XLOOKUP(A8,'Master Schedule'!$A$10:$A$90,'Master Schedule'!$B$10:$B$90)} -> 18u Girls | C8: {=XLOOKUP(A8,'Master Schedule'!$A$10:$A$90,'Master Schedule'!$D$10:$D$90)} -> 0.68402778 | D8: {=CONCATENATE(XLOOKUP(A8,'Master Schedule'!$A$10:$A$90,'Master Schedule'!$C$10:$C$90)," vs ",(XLOOKUP(A8,'Master Schedule'!$A$10:$A$90,'Master Schedule'!$E$10:$E$90)))} -> Team Orlando vs Orlando Thunder | E8: 1 | F8: {=xlookup(A8,Game_Scores!A:A,Game_Scores!J:J)} -> No_score
A9: 5 | B9: {=XLOOKUP(A9,'Master Schedule'!$A$10:$A$90,'Master Schedule'!$B$10:$B$90)} -> 16u Girls | C9: {=XLOOKUP(A9,'Master Schedule'!$A$10:$A$90,'Master Schedule'!$D$10:$D$90)} -> 0.72222222 | D9: {=CONCATENATE(XLOOKUP(A9,'Master Schedule'!$A$10:$A$90,'Master Schedule'!$C$10:$C$90)," vs ",(XLOOKUP(A9,'Master Schedule'!$A$10:$A$90,'Master Schedule'!$E$10:$E$90)))} -> Team Orlando vs Orlando Thunder 14 | E9: 1 | F9: {=xlookup(A9,Game_Scores!A:A,Game_Scores!J:J)} -> No_score
A10: 8 | B10: {=XLOOKUP(A10,'Master Schedule'!$A$10:$A$90,'Master Schedule'!$B$10:$B$90)} -> 18u Boys | C10: {=XLOOKUP(A10,'Master Schedule'!$A$10:$A$90,'Master Schedule'!$D$10:$D$90)} -> 0.76041667 | D10: {=CONCATENATE(XLOOKUP(A10,'Master Schedule'!$A$10:$A$90,'Master Schedule'!$C$10:$C$90)," vs ",(XLOOKUP(A10,'Master Schedule'!$A$10:$A$90,'Master Schedule'!$E$10:$E$90)))} -> Team Orlando vs North Idaho | E10: 1 | F10: {=xlookup(A10,Game_Scores!A:A,Game_Scores!J:J)} -> No_score
A11: 11 | B11: {=XLOOKUP(A11,'Master Schedule'!$A$10:$A$90,'Master Schedule'!$B$10:$B$90)} -> 18u Boys | C11: {=XLOOKUP(A11,'Master Schedule'!$A$10:$A$90,'Master Schedule'!$D$10:$D$90)} -> 0.79861111 | D11: {=CONCATENATE(XLOOKUP(A11,'Master Schedule'!$A$10:$A$90,'Master Schedule'!$C$10:$C$90)," vs ",(XLOOKUP(A11,'Master Schedule'!$A$10:$A$90,'Master Schedule'!$E$10:$E$90)))} -> Orlando Thunder vs Orlando United | E11: 1 | F11: {=xlookup(A11,Game_Scores!A:A,Game_Scores!J:J)} -> No_score
A12: 14 | B12: {=XLOOKUP(A12,'Master Schedule'!$A$10:$A$90,'Master Schedule'!$B$10:$B$90)} -> Masters | C12: {=XLOOKUP(A12,'Master Schedule'!$A$10:$A$90,'Master Schedule'!$D$10:$D$90)} -> 0.83333333 | D12: {=CONCATENATE(XLOOKUP(A12,'Master Schedule'!$A$10:$A$90,'Master Schedule'!$C$10:$C$90)," vs ",(XLOOKUP(A12,'Master Schedule'!$A$10:$A$90,'Master Schedule'!$E$10:$E$90)))} -> Team Orlando vs Team Orlando Black | E12: 1 | F12: {=xlookup(A12,Game_Scores!A:A,Game_Scores!J:J)} -> No_score
A13: FRI | D13: Pool 2 - Main Pool - Mid Building
A14: Game | B14: Div | C14: Time | D14: Dark vs Light | F14: Winner
A15: 3 | B15: {=XLOOKUP(A15,'Master Schedule'!$G$10:$G$90,'Master Schedule'!$H$10:$H$90)} -> 16u Boys | C15: {=XLOOKUP(A15,'Master Schedule'!$G$10:$G$90,'Master Schedule'!$J$10:$J$90)} -> 0.68402778 | D15: {=CONCATENATE(XLOOKUP(A15,'Master Schedule'!$G$10:$G$90,'Master Schedule'!$I$10:$I$90)," vs ",(XLOOKUP(A15,'Master Schedule'!$G$10:$G$90,'Master Schedule'!$K$10:$K$90)))} -> Orlando Thunder vs Orlando United | E15: 2 | F15: {=xlookup(A15,Game_Scores!A:A,Game_Scores!J:J)} -> No_score
A16: 6 | B16: {=XLOOKUP(A16,'Master Schedule'!$G$10:$G$90,'Master Schedule'!$H$10:$H$90)} -> 14u CoEd | C16: {=XLOOKUP(A16,'Master Schedule'!$G$10:$G$90,'Master Schedule'!$J$10:$J$90)} -> 0.72222222 | D16: {=CONCATENATE(XLOOKUP(A16,'Master Schedule'!$G$10:$G$90,'Master Schedule'!$I$10:$I$90)," vs ",(XLOOKUP(A16,'Master Schedule'!$G$10:$G$90,'Master Schedule'!$K$10:$K$90)))} -> Team Orlando vs Patriot | E16: 2 | F16: {=xlookup(A16,Game_Scores!A:A,Game_Scores!J:J)} -> No_score
A17: 9 | B17: {=XLOOKUP(A17,'Master Schedule'!$G$10:$G$90,'Master Schedule'!$H$10:$H$90)} -> 16u Girls | C17: {=XLOOKUP(A17,'Master Schedule'!$G$10:$G$90,'Master Schedule'!$J$10:$J$90)} -> 0.76041667 | D17: {=CONCATENATE(XLOOKUP(A17,'Master Schedule'!$G$10:$G$90,'Master Schedule'!$I$10:$I$90)," vs ",(XLOOKUP(A17,'Master Schedule'!$G$10:$G$90,'Master Schedule'!$K$10:$K$90)))} -> Orlando Thunder vs Seminole | E17: 2 | F17: {=xlookup(A17,Game_Scores!A:A,Game_Scores!J:J)} -> No_score
A18: 12 | B18: {=XLOOKUP(A18,'Master Schedule'!$G$10:$G$90,'Master Schedule'!$H$10:$H$90)} -> 16u Boys | C18: {=XLOOKUP(A18,'Master Schedule'!$G$10:$G$90,'Master Schedule'!$J$10:$J$90)} -> 0.79861111 | D18: {=CONCATENATE(XLOOKUP(A18,'Master Schedule'!$G$10:$G$90,'Master Schedule'!$I$10:$I$90)," vs ",(XLOOKUP(A18,'Master Schedule'!$G$10:$G$90,'Master Schedule'!$K$10:$K$90)))} -> Team Orlando vs Dynamo | E18: 2 | F18: {=xlookup(A18,Game_Scores!A:A,Game_Scores!J:J)} -> No_score
A19: FRI | D19: Pool 3 - Dive Well
A20: Game | B20: Div | C20: Time | D20: Dark vs Light | F20: Winner
A21: 4 | B21: {=XLOOKUP(A21,'Master Schedule'!$A$10:$A$90,'Master Schedule'!$B$10:$B$90)} -> 16u Girls | C21: {=XLOOKUP(A21,'Master Schedule'!$A$10:$A$90,'Master Schedule'!$D$10:$D$90)} -> 0.68402778 | D21: {=CONCATENATE(XLOOKUP(A21,'Master Schedule'!$A$10:$A$90,'Master Schedule'!$C$10:$C$90)," vs ",(XLOOKUP(A21,'Master Schedule'!$A$10:$A$90,'Master Schedule'!$E$10:$E$90)))} -> Orlando Thunder vs Patriot | E21: 3 | F21: {=xlookup(A21,Game_Scores!A:A,Game_Scores!J:J)} -> No_score
A22: 7 | B22: {=XLOOKUP(A22,'Master Schedule'!$A$10:$A$90,'Master Schedule'!$B$10:$B$90)} -> 14u CoEd | C22: {=XLOOKUP(A22,'Master Schedule'!$A$10:$A$90,'Master Schedule'!$D$10:$D$90)} -> 0.72222222 | D22: {=CONCATENATE(XLOOKUP(A22,'Master Schedule'!$A$10:$A$90,'Master Schedule'!$C$10:$C$90)," vs ",(XLOOKUP(A22,'Master Schedule'!$A$10:$A$90,'Master Schedule'!$E$10:$E$90)))} -> Orlando Thunder vs Orlando United | E22: 3 | F22: {=xlookup(A22,Game_Scores!A:A,Game_Scores!J:J)} -> No_score
A23: 10 | B23: {=XLOOKUP(A23,'Master Schedule'!$A$10:$A$90,'Master Schedule'!$B$10:$B$90)} -> 12u CoEd | C23: {=XLOOKUP(A23,'Master Schedule'!$A$10:$A$90,'Master Schedule'!$D$10:$D$90)} -> 0.76041667 | D23: {=CONCATENATE(XLOOKUP(A23,'Master Schedule'!$A$10:$A$90,'Master Schedule'!$C$10:$C$90)," vs ",(XLOOKUP(A23,'Master Schedule'!$A$10:$A$90,'Master Schedule'!$E$10:$E$90)))} -> Team Orlando vs Patriot | E23: 3 | F23: {=xlookup(A23,Game_Scores!A:A,Game_Scores!J:J)} -> No_score
A24: 13 | B24: {=XLOOKUP(A24,'Master Schedule'!$A$10:$A$90,'Master Schedule'!$B$10:$B$90)} -> 10u CoEd | C24: {=XLOOKUP(A24,'Master Schedule'!$A$10:$A$90,'Master Schedule'!$D$10:$D$90)} -> 0.79861111 | D24: {=CONCATENATE(XLOOKUP(A24,'Master Schedule'!$A$10:$A$90,'Master Schedule'!$C$10:$C$90)," vs ",(XLOOKUP(A24,'Master Schedule'!$A$10:$A$90,'Master Schedule'!$E$10:$E$90)))} -> Team Orlando vs Orlando Thunder | E24: 3 | F24: {=xlookup(A24,Game_Scores!A:A,Game_Scores!J:J)} -> No_score
A25: SAT | D25: Pool 1 - Main Pool - Mid Building
A26: Game | B26: Div | C26: Time | D26: Dark vs Light | F26: Winner
A27: 15 | B27: {=XLOOKUP(A27,'Master Schedule'!$A$10:$A$90,'Master Schedule'!$B$10:$B$90)} -> 18u Boys | C27: {=XLOOKUP(A27,'Master Schedule'!$A$10:$A$90,'Master Schedule'!$D$10:$D$90)} -> 0.29166667 | D27: {=CONCATENATE(XLOOKUP(A27,'Master Schedule'!$A$10:$A$90,'Master Schedule'!$C$10:$C$90)," vs ",(XLOOKUP(A27,'Master Schedule'!$A$10:$A$90,'Master Schedule'!$E$10:$E$90)))} -> Team Orlando vs Nextlevel | E27: 1 | F27: {=xlookup(A27,Game_Scores!A:A,Game_Scores!J:J)} -> No_score
A28: 18 | B28: {=XLOOKUP(A28,'Master Schedule'!$A$10:$A$90,'Master Schedule'!$B$10:$B$90)} -> 18u Boys | C28: {=XLOOKUP(A28,'Master Schedule'!$A$10:$A$90,'Master Schedule'!$D$10:$D$90)} -> 0.32986111 | D28: {=CONCATENATE(XLOOKUP(A28,'Master Schedule'!$A$10:$A$90,'Master Schedule'!$C$10:$C$90)," vs ",(XLOOKUP(A28,'Master Schedule'!$A$10:$A$90,'Master Schedule'!$E$10:$E$90)))} -> Gladiators vs Marlins | E28: 1 | F28: {=xlookup(A28,Game_Scores!A:A,Game_Scores!J:J)} -> No_score
A29: 21 | B29: {=XLOOKUP(A29,'Master Schedule'!$A$10:$A$90,'Master Schedule'!$B$10:$B$90)} -> 18u Boys | C29: {=XLOOKUP(A29,'Master Schedule'!$A$10:$A$90,'Master Schedule'!$D$10:$D$90)} -> 0.36805556 | D29: {=CONCATENATE(XLOOKUP(A29,'Master Schedule'!$A$10:$A$90,'Master Schedule'!$C$10:$C$90)," vs ",(XLOOKUP(A29,'Master Schedule'!$A$10:$A$90,'Master Schedule'!$E$10:$E$90)))} -> Orlando United vs Team Orlando Black | E29: 1 | F29: {=xlookup(A29,Game_Scores!A:A,Game_Scores!J:J)} -> No_score
A30: 24 | B30: {=XLOOKUP(A30,'Master Schedule'!$A$10:$A$90,'Master Schedule'!$B$10:$B$90)} -> 18u Boys | C30: {=XLOOKUP(A30,'Master Schedule'!$A$10:$A$90,'Master Schedule'!$D$10:$D$90)} -> 0.40625 | D30: {=CONCATENATE(XLOOKUP(A30,'Master Schedule'!$A$10:$A$90,'Master Schedule'!$C$10:$C$90)," vs ",(XLOOKUP(A30,'Master Schedule'!$A$10:$A$90,'Master Schedule'!$E$10:$E$90)))} -> North Idaho vs Nextlevel | E30: 1 | F30: {=xlookup(A30,Game_Scores!A:A,Game_Scores!J:J)} -> No_score
A31: 27 | B31: {=XLOOKUP(A31,'Master Schedule'!$A$10:$A$90,'Master Schedule'!$B$10:$B$90)} -> Masters | C31: {=XLOOKUP(A31,'Master Schedule'!$A$10:$A$90,'Master Schedule'!$D$10:$D$90)} -> 0.44444444 | D31: {=CONCATENATE(XLOOKUP(A31,'Master Schedule'!$A$10:$A$90,'Master Schedule'!$C$10:$C$90)," vs ",(XLOOKUP(A31,'Master Schedule'!$A$10:$A$90,'Master Schedule'!$E$10:$E$90)))} -> Team Orlando vs Patriot | E31: 1 | F31: {=xlookup(A31,Game_Scores!A:A,Game_Scores!J:J)} -> No_score
A32: 30 | B32: {=XLOOKUP(A32,'Master Schedule'!$A$10:$A$90,'Master Schedule'!$B$10:$B$90)} -> 18u Boys | C32: {=XLOOKUP(A32,'Master Schedule'!$A$10:$A$90,'Master Schedule'!$D$10:$D$90)} -> 0.48263889 | D32: {=CONCATENATE(XLOOKUP(A32,'Master Schedule'!$A$10:$A$90,'Master Schedule'!$C$10:$C$90)," vs ",(XLOOKUP(A32,'Master Schedule'!$A$10:$A$90,'Master Schedule'!$E$10:$E$90)))} -> Blue Dolfins vs Marlins | E32: 1 | F32: {=xlookup(A32,Game_Scores!A:A,Game_Scores!J:J)} -> No_score
A33: 33 | B33: {=XLOOKUP(A33,'Master Schedule'!$A$10:$A$90,'Master Schedule'!$B$10:$B$90)} -> Masters | C33: {=XLOOKUP(A33,'Master Schedule'!$A$10:$A$90,'Master Schedule'!$D$10:$D$90)} -> 0.52083333 | D33: {=CONCATENATE(XLOOKUP(A33,'Master Schedule'!$A$10:$A$90,'Master Schedule'!$C$10:$C$90)," vs ",(XLOOKUP(A33,'Master Schedule'!$A$10:$A$90,'Master Schedule'!$E$10:$E$90)))} -> Orlando Thunder vs Tampa | E33: 1 | F33: {=xlookup(A33,Game_Scores!A:A,Game_Scores!J:J)} -> No_score
A34: 36 | B34: {=XLOOKUP(A34,'Master Schedule'!$A$10:$A$90,'Master Schedule'!$B$10:$B$90)} -> Masters | C34: {=XLOOKUP(A34,'Master Schedule'!$A$10:$A$90,'Master Schedule'!$D$10:$D$90)} -> 0.55902778 | D34: {=CONCATENATE(XLOOKUP(A34,'Master Schedule'!$A$10:$A$90,'Master Schedule'!$C$10:$C$90)," vs ",(XLOOKUP(A34,'Master Schedule'!$A$10:$A$90,'Master Schedule'!$E$10:$E$90)))} -> Patriot vs Team Orlando Black | E34: 1 | F34: {=xlookup(A34,Game_Scores!A:A,Game_Scores!J:J)} -> No_score
A35: 39 | B35: {=XLOOKUP(A35,'Master Schedule'!$A$10:$A$90,'Master Schedule'!$B$10:$B$90)} -> 18u Boys | C35: {=XLOOKUP(A35,'Master Schedule'!$A$10:$A$90,'Master Schedule'!$D$10:$D$90)} -> 0.59722222 | D35: {=CONCATENATE(XLOOKUP(A35,'Master Schedule'!$A$10:$A$90,'Master Schedule'!$C$10:$C$90)," vs ",(XLOOKUP(A35,'Master Schedule'!$A$10:$A$90,'Master Schedule'!$E$10:$E$90)))} -> Gladiators vs Blue Dolfins | E35: 1 | F35: {=xlookup(A35,Game_Scores!A:A,Game_Scores!J:J)} -> No_score
A36: 42 | B36: {=XLOOKUP(A36,'Master Schedule'!$A$10:$A$90,'Master Schedule'!$B$10:$B$90)} -> Masters | C36: {=XLOOKUP(A36,'Master Schedule'!$A$10:$A$90,'Master Schedule'!$D$10:$D$90)} -> 0.63541667 | D36: {=CONCATENATE(XLOOKUP(A36,'Master Schedule'!$A$10:$A$90,'Master Schedule'!$C$10:$C$90)," vs ",(XLOOKUP(A36,'Master Schedule'!$A$10:$A$90,'Master Schedule'!$E$10:$E$90)))} -> Team Orlando vs Tampa | E36: 1 | F36: {=xlookup(A36,Game_Scores!A:A,Game_Scores!J:J)} -> No_score
A37: 45 | B37: {=XLOOKUP(A37,'Master Schedule'!$A$10:$A$90,'Master Schedule'!$B$10:$B$90)} -> Masters | C37: {=XLOOKUP(A37,'Master Schedule'!$A$10:$A$90,'Master Schedule'!$D$10:$D$90)} -> 0.67361111 | D37: {=CONCATENATE(XLOOKUP(A37,'Master Schedule'!$A$10:$A$90,'Master Schedule'!$C$10:$C$90)," vs ",(XLOOKUP(A37,'Master Schedule'!$A$10:$A$90,'Master Schedule'!$E$10:$E$90)))} -> Orlando Thunder vs Patriot | E37: 1 | F37: {=xlookup(A37,Game_Scores!A:A,Game_Scores!J:J)} -> No_score
A38: 47 | B38: {=XLOOKUP(A38,'Master Schedule'!$A$10:$A$90,'Master Schedule'!$B$10:$B$90)} -> 18u Boys | C38: {=XLOOKUP(A38,'Master Schedule'!$A$10:$A$90,'Master Schedule'!$D$10:$D$90)} -> 0.71180556 | D38: {=CONCATENATE(XLOOKUP(A38,'Master Schedule'!$A$10:$A$90,'Master Schedule'!$C$10:$C$90)," vs ",(XLOOKUP(A38,'Master Schedule'!$A$10:$A$90,'Master Schedule'!$E$10:$E$90)))} -> 3M vs 3N | E38: 1 | F38: {=xlookup(A38,Game_Scores!A:A,Game_Scores!J:J)} -> No_score
... A41: 56 | B41: {=XLOOKUP(A41,'Master Schedule'!$A$10:$A$90,'Master Schedule'!$B$10:$B$90)} -> 18u Boys | C41: {=XLOOKUP(A41,'Master Schedule'!$A$10:$A$90,'Master Schedule'!$D$10:$D$90)} -> 0.82638889 | D41: {=CONCATENATE(XLOOKUP(A41,'Master Schedule'!$A$10:$A$90,'Master Schedule'!$C$10:$C$90)," vs ",(XLOOKUP(A41,'Master Schedule'!$A$10:$A$90,'Master Schedule'!$E$10:$E$90)))} -> 1M vs 1O | E41: 1 | F41: {=xlookup(A41,Game_Scores!A:A,Game_Scores!J:J)} -> No_score
A42: SAT | D42: Pool 2 - Main Pool - Mid Building
A43: Game | B43: Div | C43: Time | D43: Dark vs Light | F43: Winner
A44: 16 | B44: {=XLOOKUP(A44,'Master Schedule'!$G$10:$G$90,'Master Schedule'!$H$10:$H$90)} -> 16u Boys | C44: {=XLOOKUP(A44,'Master Schedule'!$G$10:$G$90,'Master Schedule'!$J$10:$J$90)} -> 0.29166667 | D44: {=CONCATENATE(XLOOKUP(A44,'Master Schedule'!$G$10:$G$90,'Master Schedule'!$I$10:$I$90)," vs ",(XLOOKUP(A44,'Master Schedule'!$G$10:$G$90,'Master Schedule'!$K$10:$K$90)))} -> Wolverines vs Seminole | E44: 2 | F44: {=xlookup(A44,Game_Scores!A:A,Game_Scores!J:J)} -> No_score
A45: 19 | B45: {=XLOOKUP(A45,'Master Schedule'!$G$10:$G$90,'Master Schedule'!$H$10:$H$90)} -> 18u Girls | C45: {=XLOOKUP(A45,'Master Schedule'!$G$10:$G$90,'Master Schedule'!$J$10:$J$90)} -> 0.32986111 | D45: {=CONCATENATE(XLOOKUP(A45,'Master Schedule'!$G$10:$G$90,'Master Schedule'!$I$10:$I$90)," vs ",(XLOOKUP(A45,'Master Schedule'!$G$10:$G$90,'Master Schedule'!$K$10:$K$90)))} -> Team Orlando vs Patriot | E45: 2 | F45: {=xlookup(A45,Game_Scores!A:A,Game_Scores!J:J)} -> No_score
A46: 22 | B46: {=XLOOKUP(A46,'Master Schedule'!$G$10:$G$90,'Master Schedule'!$H$10:$H$90)} -> 16u Boys | C46: {=XLOOKUP(A46,'Master Schedule'!$G$10:$G$90,'Master Schedule'!$J$10:$J$90)} -> 0.36805556 | D46: {=CONCATENATE(XLOOKUP(A46,'Master Schedule'!$G$10:$G$90,'Master Schedule'!$I$10:$I$90)," vs ",(XLOOKUP(A46,'Master Schedule'!$G$10:$G$90,'Master Schedule'!$K$10:$K$90)))} -> Orlando Thunder vs Gladiators | E46: 2 | F46: {=xlookup(A46,Game_Scores!A:A,Game_Scores!J:J)} -> No_score
...

Sheet Master Schedule
A6: 46157
A8: Pool 1 - Main Pool - Scoreboard | G8: Pool 2 - Main Pool - Mid Building
A9: Game | B9: Div | C9: Dark Caps | D9: Time | E9: Light Caps | G9: Game | H9: Div | I9: Dark Caps | J9: Time | K9: Light Caps
A10: 1 | B10: 18u Boys | C10: Orlando Thunder | D10: 0.64583333 | E10: Team Orlando Black | H10: ---- | I10: --- | J10: 0.64583333 | K10: ---
A11: 2 | B11: 18u Girls | C11: Team Orlando | D11: 0.68402778 | E11: Orlando Thunder | G11: 3 | H11: 16u Boys | I11: Orlando Thunder | J11: 0.68402778 | K11: Orlando United
A12: 5 | B12: 16u Girls | C12: Team Orlando | D12: 0.72222222 | E12: Orlando Thunder 14 | G12: 6 | H12: 14u CoEd | I12: Team Orlando | J12: 0.72222222 | K12: Patriot
A13: 8 | B13: 18u Boys | C13: Team Orlando | D13: 0.76041667 | E13: North Idaho | G13: 9 | H13: 16u Girls | I13: Orlando Thunder | J13: 0.76041667 | K13: Seminole
A14: 11 | B14: 18u Boys | C14: Orlando Thunder | D14: 0.79861111 | E14: Orlando United | G14: 12 | H14: 16u Boys | I14: Team Orlando | J14: 0.79861111 | K14: Dynamo
A15: 14 | B15: Masters | C15: Team Orlando | D15: 0.83333333 | E15: Team Orlando Black | H15: ---- | I15: --- | J15: 0.83333333 | K15: ---
A17: Pool 3 - Dive Well
A18: Game | B18: Div | C18: Dark Caps | D18: Time | E18: Light Caps
B19: ---- | C19: --- | D19: 0.64583333 | E19: ---
A20: 4 | B20: 16u Girls | C20: Orlando Thunder | D20: 0.68402778 | E20: Patriot
A21: 7 | B21: 14u CoEd | C21: Orlando Thunder | D21: 0.72222222 | E21: Orlando United
A22: 10 | B22: 12u CoEd | C22: Team Orlando | D22: 0.76041667 | E22: Patriot
A23: 13 | B23: 10u CoEd | C23: Team Orlando | D23: 0.79861111 | E23: Orlando Thunder
B24: ---- | C24: --- | D24: 0.83333333 | E24: ---
A26: 46158
A28: Pool 1 - Main Pool - Scoreboard | G28: Pool 2 - Main Pool - Mid Building
A29: Game | B29: Div | C29: Dark Caps | D29: Time | E29: Light Caps | G29: Game | H29: Div | I29: Dark Caps | J29: Time | K29: Light Caps
A30: 15 | B30: 18u Boys | C30: Team Orlando | D30: 0.29166667 | E30: Nextlevel | G30: 16 | H30: 16u Boys | I30: Wolverines | J30: 0.29166667 | K30: Seminole
A31: 18 | B31: 18u Boys | C31: Gladiators | D31: 0.32986111 | E31: Marlins | G31: 19 | H31: 18u Girls | I31: Team Orlando | J31: 0.32986111 | K31: Patriot
A32: 21 | B32: 18u Boys | C32: Orlando United | D32: 0.36805556 | E32: Team Orlando Black | G32: 22 | H32: 16u Boys | I32: Orlando Thunder | J32: 0.36805556 | K32: Gladiators
A33: 24 | B33: 18u Boys | C33: North Idaho | D33: 0.40625 | E33: Nextlevel | G33: 25 | H33: 16u Girls | I33: Team Orlando | J33: 0.40625 | K33: Orlando United
A34: 27 | B34: Masters | C34: Team Orlando | D34: 0.44444444 | E34: Patriot | G34: 28 | H34: 16u Girls | I34: Seminole | J34: 0.44444444 | K34: Patriot
A35: 30 | B35: 18u Boys | C35: Blue Dolfins | D35: 0.48263889 | E35: Marlins | G35: 31 | H35: 16u Boys | I35: Orlando United | J35: 0.48263889 | K35: Marlins
A36: 33 | B36: Masters | C36: Orlando Thunder | D36: 0.52083333 | E36: Tampa | G36: 34 | H36: 16u Boys | I36: Dynamo | J36: 0.52083333 | K36: Seminole
A37: 36 | B37: Masters | C37: Patriot | D37: 0.55902778 | E37: Team Orlando Black | G37: 37 | H37: 18u Girls | I37: Patriot | J37: 0.55902778 | K37: Orlando Thunder
A38: 39 | B38: 18u Boys | C38: Gladiators | D38: 0.59722222 | E38: Blue Dolfins | G38: 40 | H38: 16u Girls | I38: Orlando United | J38: 0.59722222 | K38: Orlando Thunder 14
A39: 42 | B39: Masters | C39: Team Orlando | D39: 0.63541667 | E39: Tampa | G39: 43 | H39: 16u Boys | I39: Gladiators | J39: 0.63541667 | K39: Orlando United
A40: 45 | B40: Masters | C40: Orlando Thunder | D40: 0.67361111 | E40: Patriot | G40: 46 | H40: 16u Boys | I40: Orlando Thunder | J40: 0.67361111 | K40: Marlins
A41: 47 | B41: 18u Boys | C41: 3M | D41: 0.71180556 | E41: 3N | G41: 48 | H41: 16u Boys | I41: Wolverines | J41: 0.71180556 | K41: Dynamo
... A44: 56 | B44: 18u Boys | C44: 1M | D44: 0.82638889 | E44: 1O | G44: 57 | H44: 14u CoEd | I44: 3D | J44: 0.82638889 | K44: 3E
A46: Pool 3 - Dive Well
A47: Game | B47: Div | C47: Dark Caps | D47: Time | E47: Light Caps
A48: 17 | B48: 12u CoEd | C48: Team Orlando | D48: 0.29166667 | E48: Orlando Thunder
A49: 20 | B49: 12u CoEd | C49: Gladiators | D49: 0.32986111 | E49: Patriot
A50: 23 | B50: 10u CoEd | C50: Orlando Thunder | D50: 0.36805556 | E50: Team Orlando
A51: 26 | B51: 14u CoEd | C51: Patriot | D51: 0.40625 | E51: Wolverines Blue
A52: 29 | B52: 14u CoEd | C52: Orlando Thunder | D52: 0.44444444 | E52: St. Andrews
...

Sheet Game_Scores
A1: GM | B1: Div | C1: Day | D1: Pool | E1: Time | F1: Dark caps | G1: Dk Score | H1: Light caps | I1: Lt Score | J1: Winner
A2: 1 | B2: {=XLOOKUP(A2,'Mobile Friendly'!A:A,'Mobile Friendly'!B:B)} -> 18u Boys | C2: Fri | D2: {=XLOOKUP(A2,'Mobile Friendly'!A:A,'Mobile Friendly'!E:E)} -> 1 | E2: {=XLOOKUP(A2,'Mobile Friendly'!A:A,'Mobile Friendly'!C:C)} -> 0.64583333 | F2: {=XLOOKUP(A2,'Master Schedule'!$A$10:$A$90,'Master Schedule'!$C$10:$C$90)} -> Orlando Thunder | H2: {=XLOOKUP(A2,'Master Schedule'!$A$10:$A$90,'Master Schedule'!$E$10:$E$90)} -> Team Orlando Black | J2: =ifs(G2=I2,"No_score",G2>I2,F2,I2>G2,H2) -> No_score
A3: 2 | B3: {=XLOOKUP(A3,'Mobile Friendly'!A:A,'Mobile Friendly'!B:B)} -> 18u Girls | C3: Fri | D3: {=XLOOKUP(A3,'Mobile Friendly'!A:A,'Mobile Friendly'!E:E)} -> 1 | E3: {=XLOOKUP(A3,'Mobile Friendly'!A:A,'Mobile Friendly'!C:C)} -> 0.68402778 | F3: {=XLOOKUP(A3,'Master Schedule'!$A$10:$A$90,'Master Schedule'!$C$10:$C$90)} -> Team Orlando | H3: {=XLOOKUP(A3,'Master Schedule'!$A$10:$A$90,'Master Schedule'!$E$10:$E$90)} -> Orlando Thunder | J3: =ifs(G3=I3,"No_score",G3>I3,F3,I3>G3,H3) -> No_score
A4: 3 | B4: {=XLOOKUP(A4,'Mobile Friendly'!A:A,'Mobile Friendly'!B:B)} -> 16u Boys | C4: Fri | D4: {=XLOOKUP(A4,'Mobile Friendly'!A:A,'Mobile Friendly'!E:E)} -> 2 | E4: {=XLOOKUP(A4,'Mobile Friendly'!A:A,'Mobile Friendly'!C:C)} -> 0.68402778 | F4: {=XLOOKUP(A4,'Master Schedule'!$G$10:$G$90,'Master Schedule'!$I$10:$I$90)} -> Orlando Thunder | H4: {=XLOOKUP(A4,'Master Schedule'!$G$10:$G$90,'Master Schedule'!$K$10:$K$90)} -> Orlando United | J4: =ifs(G4=I4,"No_score",G4>I4,F4,I4>G4,H4) -> No_score
A5: 4 | B5: {=XLOOKUP(A5,'Mobile Friendly'!A:A,'Mobile Friendly'!B:B)} -> 16u Girls | C5: Fri | D5: {=XLOOKUP(A5,'Mobile Friendly'!A:A,'Mobile Friendly'!E:E)} -> 3 | E5: {=XLOOKUP(A5,'Mobile Friendly'!A:A,'Mobile Friendly'!C:C)} -> 0.68402778 | F5: {=XLOOKUP(A5,'Master Schedule'!$A$10:$A$90,'Master Schedule'!$C$10:$C$90)} -> Orlando Thunder | H5: {=XLOOKUP(A5,'Master Schedule'!$A$10:$A$90,'Master Schedule'!$E$10:$E$90)} -> Patriot | J5: =ifs(G5=I5,"No_score",G5>I5,F5,I5>G5,H5) -> No_score
A6: 5 | B6: {=XLOOKUP(A6,'Mobile Friendly'!A:A,'Mobile Friendly'!B:B)} -> 16u Girls | C6: Fri | D6: {=XLOOKUP(A6,'Mobile Friendly'!A:A,'Mobile Friendly'!E:E)} -> 1 | E6: {=XLOOKUP(A6,'Mobile Friendly'!A:A,'Mobile Friendly'!C:C)} -> 0.72222222 | F6: {=XLOOKUP(A6,'Master Schedule'!$A$10:$A$90,'Master Schedule'!$C$10:$C$90)} -> Team Orlando | H6: {=XLOOKUP(A6,'Master Schedule'!$A$10:$A$90,'Master Schedule'!$E$10:$E$90)} -> Orlando Thunder 14 | J6: =ifs(G6=I6,"No_score",G6>I6,F6,I6>G6,H6) -> No_score
A7: 6 | B7: {=XLOOKUP(A7,'Mobile Friendly'!A:A,'Mobile Friendly'!B:B)} -> 14u CoEd | C7: Fri | D7: {=XLOOKUP(A7,'Mobile Friendly'!A:A,'Mobile Friendly'!E:E)} -> 2 | E7: {=XLOOKUP(A7,'Mobile Friendly'!A:A,'Mobile Friendly'!C:C)} -> 0.72222222 | F7: {=XLOOKUP(A7,'Master Schedule'!$G$10:$G$90,'Master Schedule'!$I$10:$I$90)} -> Team Orlando | H7: {=XLOOKUP(A7,'Master Schedule'!$G$10:$G$90,'Master Schedule'!$K$10:$K$90)} -> Patriot | J7: =ifs(G7=I7,"No_score",G7>I7,F7,I7>G7,H7) -> No_score
A8: 7 | B8: {=XLOOKUP(A8,'Mobile Friendly'!A:A,'Mobile Friendly'!B:B)} -> 14u CoEd | C8: Fri | D8: {=XLOOKUP(A8,'Mobile Friendly'!A:A,'Mobile Friendly'!E:E)} -> 3 | E8: {=XLOOKUP(A8,'Mobile Friendly'!A:A,'Mobile Friendly'!C:C)} -> 0.72222222 | F8: {=XLOOKUP(A8,'Master Schedule'!$A$10:$A$90,'Master Schedule'!$C$10:$C$90)} -> Orlando Thunder | H8: {=XLOOKUP(A8,'Master Schedule'!$A$10:$A$90,'Master Schedule'!$E$10:$E$90)} -> Orlando United | J8: =ifs(G8=I8,"No_score",G8>I8,F8,I8>G8,H8) -> No_score
A9: 8 | B9: {=XLOOKUP(A9,'Mobile Friendly'!A:A,'Mobile Friendly'!B:B)} -> 18u Boys | C9: Fri | D9: {=XLOOKUP(A9,'Mobile Friendly'!A:A,'Mobile Friendly'!E:E)} -> 1 | E9: {=XLOOKUP(A9,'Mobile Friendly'!A:A,'Mobile Friendly'!C:C)} -> 0.76041667 | F9: {=XLOOKUP(A9,'Master Schedule'!$A$10:$A$90,'Master Schedule'!$C$10:$C$90)} -> Team Orlando | H9: {=XLOOKUP(A9,'Master Schedule'!$A$10:$A$90,'Master Schedule'!$E$10:$E$90)} -> North Idaho | J9: =ifs(G9=I9,"No_score",G9>I9,F9,I9>G9,H9) -> No_score
A10: 9 | B10: {=XLOOKUP(A10,'Mobile Friendly'!A:A,'Mobile Friendly'!B:B)} -> 16u Girls | C10: Fri | D10: {=XLOOKUP(A10,'Mobile Friendly'!A:A,'Mobile Friendly'!E:E)} -> 2 | E10: {=XLOOKUP(A10,'Mobile Friendly'!A:A,'Mobile Friendly'!C:C)} -> 0.76041667 | F10: {=XLOOKUP(A10,'Master Schedule'!$G$10:$G$90,'Master Schedule'!$I$10:$I$90)} -> Orlando Thunder | H10: {=XLOOKUP(A10,'Master Schedule'!$G$10:$G$90,'Master Schedule'!$K$10:$K$90)} -> Seminole | J10: =ifs(G10=I10,"No_score",G10>I10,F10,I10>G10,H10) -> No_score
A11: 10 | B11: {=XLOOKUP(A11,'Mobile Friendly'!A:A,'Mobile Friendly'!B:B)} -> 12u CoEd | C11: Fri | D11: {=XLOOKUP(A11,'Mobile Friendly'!A:A,'Mobile Friendly'!E:E)} -> 3 | E11: {=XLOOKUP(A11,'Mobile Friendly'!A:A,'Mobile Friendly'!C:C)} -> 0.76041667 | F11: {=XLOOKUP(A11,'Master Schedule'!$A$10:$A$90,'Master Schedule'!$C$10:$C$90)} -> Team Orlando | H11: {=XLOOKUP(A11,'Master Schedule'!$A$10:$A$90,'Master Schedule'!$E$10:$E$90)} -> Patriot | J11: =ifs(G11=I11,"No_score",G11>I11,F11,I11>G11,H11) -> No_score
A12: 11 | B12: {=XLOOKUP(A12,'Mobile Friendly'!A:A,'Mobile Friendly'!B:B)} -> 18u Boys | C12: Fri | D12: {=XLOOKUP(A12,'Mobile Friendly'!A:A,'Mobile Friendly'!E:E)} -> 1 | E12: {=XLOOKUP(A12,'Mobile Friendly'!A:A,'Mobile Friendly'!C:C)} -> 0.79861111 | F12: {=XLOOKUP(A12,'Master Schedule'!$A$10:$A$90,'Master Schedule'!$C$10:$C$90)} -> Orlando Thunder | H12: {=XLOOKUP(A12,'Master Schedule'!$A$10:$A$90,'Master Schedule'!$E$10:$E$90)} -> Orlando United | J12: =ifs(G12=I12,"No_score",G12>I12,F12,I12>G12,H12) -> No_score
A13: 12 | B13: {=XLOOKUP(A13,'Mobile Friendly'!A:A,'Mobile Friendly'!B:B)} -> 16u Boys | C13: Fri | D13: {=XLOOKUP(A13,'Mobile Friendly'!A:A,'Mobile Friendly'!E:E)} -> 2 | E13: {=XLOOKUP(A13,'Mobile Friendly'!A:A,'Mobile Friendly'!C:C)} -> 0.79861111 | F13: {=XLOOKUP(A13,'Master Schedule'!$G$10:$G$90,'Master Schedule'!$I$10:$I$90)} -> Team Orlando | H13: {=XLOOKUP(A13,'Master Schedule'!$G$10:$G$90,'Master Schedule'!$K$10:$K$90)} -> Dynamo | J13: =ifs(G13=I13,"No_score",G13>I13,F13,I13>G13,H13) -> No_score
A14: 13 | B14: {=XLOOKUP(A14,'Mobile Friendly'!A:A,'Mobile Friendly'!B:B)} -> 10u CoEd | C14: Fri | D14: {=XLOOKUP(A14,'Mobile Friendly'!A:A,'Mobile Friendly'!E:E)} -> 3 | E14: {=XLOOKUP(A14,'Mobile Friendly'!A:A,'Mobile Friendly'!C:C)} -> 0.79861111 | F14: {=XLOOKUP(A14,'Master Schedule'!$A$10:$A$90,'Master Schedule'!$C$10:$C$90)} -> Team Orlando | H14: {=XLOOKUP(A14,'Master Schedule'!$A$10:$A$90,'Master Schedule'!$E$10:$E$90)} -> Orlando Thunder | J14: =ifs(G14=I14,"No_score",G14>I14,F14,I14>G14,H14) -> No_score
A15: 14 | B15: {=XLOOKUP(A15,'Mobile Friendly'!A:A,'Mobile Friendly'!B:B)} -> Masters | C15: Fri | D15: {=XLOOKUP(A15,'Mobile Friendly'!A:A,'Mobile Friendly'!E:E)} -> 1 | E15: {=XLOOKUP(A15,'Mobile Friendly'!A:A,'Mobile Friendly'!C:C)} -> 0.83333333 | F15: {=XLOOKUP(A15,'Master Schedule'!$A$10:$A$90,'Master Schedule'!$C$10:$C$90)} -> Team Orlando | H15: {=XLOOKUP(A15,'Master Schedule'!$A$10:$A$90,'Master Schedule'!$E$10:$E$90)} -> Team Orlando Black | J15: =ifs(G15=I15,"No_score",G15>I15,F15,I15>G15,H15) -> No_score
A16: 15 | B16: {=XLOOKUP(A16,'Mobile Friendly'!A:A,'Mobile Friendly'!B:B)} -> 18u Boys | C16: Sat | D16: {=XLOOKUP(A16,'Mobile Friendly'!A:A,'Mobile Friendly'!E:E)} -> 1 | E16: {=XLOOKUP(A16,'Mobile Friendly'!A:A,'Mobile Friendly'!C:C)} -> 0.29166667 | F16: {=XLOOKUP(A16,'Master Schedule'!$A$10:$A$90,'Master Schedule'!$C$10:$C$90)} -> Team Orlando | H16: {=XLOOKUP(A16,'Master Schedule'!$A$10:$A$90,'Master Schedule'!$E$10:$E$90)} -> Nextlevel | J16: =ifs(G16=I16,"No_score",G16>I16,F16,I16>G16,H16) -> No_score
A17: 16 | B17: {=XLOOKUP(A17,'Mobile Friendly'!A:A,'Mobile Friendly'!B:B)} -> 16u Boys | C17: Sat | D17: {=XLOOKUP(A17,'Mobile Friendly'!A:A,'Mobile Friendly'!E:E)} -> 2 | E17: {=XLOOKUP(A17,'Mobile Friendly'!A:A,'Mobile Friendly'!C:C)} -> 0.29166667 | F17: {=XLOOKUP(A17,'Master Schedule'!$G$10:$G$90,'Master Schedule'!$I$10:$I$90)} -> Wolverines | H17: {=XLOOKUP(A17,'Master Schedule'!$G$10:$G$90,'Master Schedule'!$K$10:$K$90)} -> Seminole | J17: =ifs(G17=I17,"No_score",G17>I17,F17,I17>G17,H17) -> No_score
A18: 17 | B18: {=XLOOKUP(A18,'Mobile Friendly'!A:A,'Mobile Friendly'!B:B)} -> 12u CoEd | C18: Sat | D18: {=XLOOKUP(A18,'Mobile Friendly'!A:A,'Mobile Friendly'!E:E)} -> 3 | E18: {=XLOOKUP(A18,'Mobile Friendly'!A:A,'Mobile Friendly'!C:C)} -> 0.29166667 | F18: {=XLOOKUP(A18,'Master Schedule'!$A$10:$A$90,'Master Schedule'!$C$10:$C$90)} -> Team Orlando | H18: {=XLOOKUP(A18,'Master Schedule'!$A$10:$A$90,'Master Schedule'!$E$10:$E$90)} -> Orlando Thunder | J18: =ifs(G18=I18,"No_score",G18>I18,F18,I18>G18,H18) -> No_score
A19: 18 | B19: {=XLOOKUP(A19,'Mobile Friendly'!A:A,'Mobile Friendly'!B:B)} -> 18u Boys | C19: Sat | D19: {=XLOOKUP(A19,'Mobile Friendly'!A:A,'Mobile Friendly'!E:E)} -> 1 | E19: {=XLOOKUP(A19,'Mobile Friendly'!A:A,'Mobile Friendly'!C:C)} -> 0.32986111 | F19: {=XLOOKUP(A19,'Master Schedule'!$A$10:$A$90,'Master Schedule'!$C$10:$C$90)} -> Gladiators | H19: {=XLOOKUP(A19,'Master Schedule'!$A$10:$A$90,'Master Schedule'!$E$10:$E$90)} -> Marlins | J19: =ifs(G19=I19,"No_score",G19>I19,F19,I19>G19,H19) -> No_score
A20: 19 | B20: {=XLOOKUP(A20,'Mobile Friendly'!A:A,'Mobile Friendly'!B:B)} -> 18u Girls | C20: Sat | D20: {=XLOOKUP(A20,'Mobile Friendly'!A:A,'Mobile Friendly'!E:E)} -> 2 | E20: {=XLOOKUP(A20,'Mobile Friendly'!A:A,'Mobile Friendly'!C:C)} -> 0.32986111 | F20: {=XLOOKUP(A20,'Master Schedule'!$G$10:$G$90,'Master Schedule'!$I$10:$I$90)} -> Team Orlando | H20: {=XLOOKUP(A20,'Master Schedule'!$G$10:$G$90,'Master Schedule'!$K$10:$K$90)} -> Patriot | J20: =ifs(G20=I20,"No_score",G20>I20,F20,I20>G20,H20) -> No_score
A21: 20 | B21: {=XLOOKUP(A21,'Mobile Friendly'!A:A,'Mobile Friendly'!B:B)} -> 12u CoEd | C21: Sat | D21: {=XLOOKUP(A21,'Mobile Friendly'!A:A,'Mobile Friendly'!E:E)} -> 3 | E21: {=XLOOKUP(A21,'Mobile Friendly'!A:A,'Mobile Friendly'!C:C)} -> 0.32986111 | F21: {=XLOOKUP(A21,'Master Schedule'!$A$10:$A$90,'Master Schedule'!$C$10:$C$90)} -> Gladiators | H21: {=XLOOKUP(A21,'Master Schedule'!$A$10:$A$90,'Master Schedule'!$E$10:$E$90)} -> Patriot | J21: =ifs(G21=I21,"No_score",G21>I21,F21,I21>G21,H21) -> No_score
A22: 21 | B22: {=XLOOKUP(A22,'Mobile Friendly'!A:A,'Mobile Friendly'!B:B)} -> 18u Boys | C22: Sat | D22: {=XLOOKUP(A22,'Mobile Friendly'!A:A,'Mobile Friendly'!E:E)} -> 1 | E22: {=XLOOKUP(A22,'Mobile Friendly'!A:A,'Mobile Friendly'!C:C)} -> 0.36805556 | F22: {=XLOOKUP(A22,'Master Schedule'!$A$10:$A$90,'Master Schedule'!$C$10:$C$90)} -> Orlando United | H22: {=XLOOKUP(A22,'Master Schedule'!$A$10:$A$90,'Master Schedule'!$E$10:$E$90)} -> Team Orlando Black | J22: =ifs(G22=I22,"No_score",G22>I22,F22,I22>G22,H22) -> No_score
A23: 22 | B23: {=XLOOKUP(A23,'Mobile Friendly'!A:A,'Mobile Friendly'!B:B)} -> 16u Boys | C23: Sat | D23: {=XLOOKUP(A23,'Mobile Friendly'!A:A,'Mobile Friendly'!E:E)} -> 2 | E23: {=XLOOKUP(A23,'Mobile Friendly'!A:A,'Mobile Friendly'!C:C)} -> 0.36805556 | F23: {=XLOOKUP(A23,'Master Schedule'!$G$10:$G$90,'Master Schedule'!$I$10:$I$90)} -> Orlando Thunder | H23: {=XLOOKUP(A23,'Master Schedule'!$G$10:$G$90,'Master Schedule'!$K$10:$K$90)} -> Gladiators | J23: =ifs(G23=I23,"No_score",G23>I23,F23,I23>G23,H23) -> No_score
A24: 23 | B24: {=XLOOKUP(A24,'Mobile Friendly'!A:A,'Mobile Friendly'!B:B)} -> 10u CoEd | C24: Sat | D24: {=XLOOKUP(A24,'Mobile Friendly'!A:A,'Mobile Friendly'!E:E)} -> 3 | E24: {=XLOOKUP(A24,'Mobile Friendly'!A:A,'Mobile Friendly'!C:C)} -> 0.36805556 | F24: {=XLOOKUP(A24,'Master Schedule'!$A$10:$A$90,'Master Schedule'!$C$10:$C$90)} -> Orlando Thunder | H24: {=XLOOKUP(A24,'Master Schedule'!$A$10:$A$90,'Master Schedule'!$E$10:$E$90)} -> Team Orlando | J24: =ifs(G24=I24,"No_score",G24>I24,F24,I24>G24,H24) -> No_score
A25: 24 | B25: {=XLOOKUP(A25,'Mobile Friendly'!A:A,'Mobile Friendly'!B:B)} -> 18u Boys | C25: Sat | D25: {=XLOOKUP(A25,'Mobile Friendly'!A:A,'Mobile Friendly'!E:E)} -> 1 | E25: {=XLOOKUP(A25,'Mobile Friendly'!A:A,'Mobile Friendly'!C:C)} -> 0.40625 | F25: {=XLOOKUP(A25,'Master Schedule'!$A$10:$A$90,'Master Schedule'!$C$10:$C$90)} -> North Idaho | H25: {=XLOOKUP(A25,'Master Schedule'!$A$10:$A$90,'Master Schedule'!$E$10:$E$90)} -> Nextlevel | J25: =ifs(G25=I25,"No_score",G25>I25,F25,I25>G25,H25) -> No_score
A26: 25 | B26: {=XLOOKUP(A26,'Mobile Friendly'!A:A,'Mobile Friendly'!B:B)} -> 16u Girls | C26: Sat | D26: {=XLOOKUP(A26,'Mobile Friendly'!A:A,'Mobile Friendly'!E:E)} -> 2 | E26: {=XLOOKUP(A26,'Mobile Friendly'!A:A,'Mobile Friendly'!C:C)} -> 0.40625 | F26: {=XLOOKUP(A26,'Master Schedule'!$G$10:$G$90,'Master Schedule'!$I$10:$I$90)} -> Team Orlando | H26: {=XLOOKUP(A26,'Master Schedule'!$G$10:$G$90,'Master Schedule'!$K$10:$K$90)} -> Orlando United | J26: =ifs(G26=I26,"No_score",G26>I26,F26,I26>G26,H26) -> No_score
A27: 26 | B27: {=XLOOKUP(A27,'Mobile Friendly'!A:A,'Mobile Friendly'!B:B)} -> 14u CoEd | C27: Sat | D27: {=XLOOKUP(A27,'Mobile Friendly'!A:A,'Mobile Friendly'!E:E)} -> 3 | E27: {=XLOOKUP(A27,'Mobile Friendly'!A:A,'Mobile Friendly'!C:C)} -> 0.40625 | F27: {=XLOOKUP(A27,'Master Schedule'!$A$10:$A$90,'Master Schedule'!$C$10:$C$90)} -> Patriot | H27: {=XLOOKUP(A27,'Master Schedule'!$A$10:$A$90,'Master Schedule'!$E$10:$E$90)} -> Wolverines Blue | J27: =ifs(G27=I27,"No_score",G27>I27,F27,I27>G27,H27) -> No_score
A28: 27 | B28: {=XLOOKUP(A28,'Mobile Friendly'!A:A,'Mobile Friendly'!B:B)} -> Masters | C28: Sat | D28: {=XLOOKUP(A28,'Mobile Friendly'!A:A,'Mobile Friendly'!E:E)} -> 1 | E28: {=XLOOKUP(A28,'Mobile Friendly'!A:A,'Mobile Friendly'!C:C)} -> 0.44444444 | F28: {=XLOOKUP(A28,'Master Schedule'!$A$10:$A$90,'Master Schedule'!$C$10:$C$90)} -> Team Orlando | H28: {=XLOOKUP(A28,'Master Schedule'!$A$10:$A$90,'Master Schedule'!$E$10:$E$90)} -> Patriot | J28: =ifs(G28=I28,"No_score",G28>I28,F28,I28>G28,H28) -> No_score
A29: 28 | B29: {=XLOOKUP(A29,'Mobile Friendly'!A:A,'Mobile Friendly'!B:B)} -> 16u Girls | C29: Sat | D29: {=XLOOKUP(A29,'Mobile Friendly'!A:A,'Mobile Friendly'!E:E)} -> 2 | E29: {=XLOOKUP(A29,'Mobile Friendly'!A:A,'Mobile Friendly'!C:C)} -> 0.44444444 | F29: {=XLOOKUP(A29,'Master Schedule'!$G$10:$G$90,'Master Schedule'!$I$10:$I$90)} -> Seminole | H29: {=XLOOKUP(A29,'Master Schedule'!$G$10:$G$90,'Master Schedule'!$K$10:$K$90)} -> Patriot | J29: =ifs(G29=I29,"No_score",G29>I29,F29,I29>G29,H29) -> No_score
A30: 29 | B30: {=XLOOKUP(A30,'Mobile Friendly'!A:A,'Mobile Friendly'!B:B)} -> 14u CoEd | C30: Sat | D30: {=XLOOKUP(A30,'Mobile Friendly'!A:A,'Mobile Friendly'!E:E)} -> 3 | E30: {=XLOOKUP(A30,'Mobile Friendly'!A:A,'Mobile Friendly'!C:C)} -> 0.44444444 | F30: {=XLOOKUP(A30,'Master Schedule'!$A$10:$A$90,'Master Schedule'!$C$10:$C$90)} -> Orlando Thunder | H30: {=XLOOKUP(A30,'Master Schedule'!$A$10:$A$90,'Master Schedule'!$E$10:$E$90)} -> St. Andrews | J30: =ifs(G30=I30,"No_score",G30>I30,F30,I30>G30,H30) -> No_score
A31: 30 | B31: {=XLOOKUP(A31,'Mobile Friendly'!A:A,'Mobile Friendly'!B:B)} -> 18u Boys | C31: Sat | D31: {=XLOOKUP(A31,'Mobile Friendly'!A:A,'Mobile Friendly'!E:E)} -> 1 | E31: {=XLOOKUP(A31,'Mobile Friendly'!A:A,'Mobile Friendly'!C:C)} -> 0.48263889 | F31: {=XLOOKUP(A31,'Master Schedule'!$A$10:$A$90,'Master Schedule'!$C$10:$C$90)} -> Blue Dolfins | H31: {=XLOOKUP(A31,'Master Schedule'!$A$10:$A$90,'Master Schedule'!$E$10:$E$90)} -> Marlins | J31: =ifs(G31=I31,"No_score",G31>I31,F31,I31>G31,H31) -> No_score
A32: 31 | B32: {=XLOOKUP(A32,'Mobile Friendly'!A:A,'Mobile Friendly'!B:B)} -> 16u Boys | C32: Sat | D32: {=XLOOKUP(A32,'Mobile Friendly'!A:A,'Mobile Friendly'!E:E)} -> 2 | E32: {=XLOOKUP(A32,'Mobile Friendly'!A:A,'Mobile Friendly'!C:C)} -> 0.48263889 | F32: {=XLOOKUP(A32,'Master Schedule'!$G$10:$G$90,'Master Schedule'!$I$10:$I$90)} -> Orlando United | H32: {=XLOOKUP(A32,'Master Schedule'!$G$10:$G$90,'Master Schedule'!$K$10:$K$90)} -> Marlins | J32: =ifs(G32=I32,"No_score",G32>I32,F32,I32>G32,H32) -> No_score
A33: 32 | B33: {=XLOOKUP(A33,'Mobile Friendly'!A:A,'Mobile Friendly'!B:B)} -> 14u CoEd | C33: Sat | D33: {=XLOOKUP(A33,'Mobile Friendly'!A:A,'Mobile Friendly'!E:E)} -> 3 | E33: {=XLOOKUP(A33,'Mobile Friendly'!A:A,'Mobile Friendly'!C:C)} -> 0.48263889 | F33: {=XLOOKUP(A33,'Master Schedule'!$A$10:$A$90,'Master Schedule'!$C$10:$C$90)} -> Seminole | H33: {=XLOOKUP(A33,'Master Schedule'!$A$10:$A$90,'Master Schedule'!$E$10:$E$90)} -> Gladiators | J33: =ifs(G33=I33,"No_score",G33>I33,F33,I33>G33,H33) -> No_score
A34: 33 | B34: {=XLOOKUP(A34,'Mobile Friendly'!A:A,'Mobile Friendly'!B:B)} -> Masters | C34: Sat | D34: {=XLOOKUP(A34,'Mobile Friendly'!A:A,'Mobile Friendly'!E:E)} -> 1 | E34: {=XLOOKUP(A34,'Mobile Friendly'!A:A,'Mobile Friendly'!C:C)} -> 0.52083333 | F34: {=XLOOKUP(A34,'Master Schedule'!$A$10:$A$90,'Master Schedule'!$C$10:$C$90)} -> Orlando Thunder | H34: {=XLOOKUP(A34,'Master Schedule'!$A$10:$A$90,'Master Schedule'!$E$10:$E$90)} -> Tampa | J34: =ifs(G34=I34,"No_score",G34>I34,F34,I34>G34,H34) -> No_score
A35: 34 | B35: {=XLOOKUP(A35,'Mobile Friendly'!A:A,'Mobile Friendly'!B:B)} -> 16u Boys | C35: Sat | D35: {=XLOOKUP(A35,'Mobile Friendly'!A:A,'Mobile Friendly'!E:E)} -> 2 | E35: {=XLOOKUP(A35,'Mobile Friendly'!A:A,'Mobile Friendly'!C:C)} -> 0.52083333 | F35: {=XLOOKUP(A35,'Master Schedule'!$G$10:$G$90,'Master Schedule'!$I$10:$I$90)} -> Dynamo | H35: {=XLOOKUP(A35,'Master Schedule'!$G$10:$G$90,'Master Schedule'!$K$10:$K$90)} -> Seminole | J35: =ifs(G35=I35,"No_score",G35>I35,F35,I35>G35,H35) -> No_score
A36: 35 | B36: {=XLOOKUP(A36,'Mobile Friendly'!A:A,'Mobile Friendly'!B:B)} -> 14u CoEd | C36: Sat | D36: {=XLOOKUP(A36,'Mobile Friendly'!A:A,'Mobile Friendly'!E:E)} -> 3 | E36: {=XLOOKUP(A36,'Mobile Friendly'!A:A,'Mobile Friendly'!C:C)} -> 0.52083333 | F36: {=XLOOKUP(A36,'Master Schedule'!$A$10:$A$90,'Master Schedule'!$C$10:$C$90)} -> Team Orlando | H36: {=XLOOKUP(A36,'Master Schedule'!$A$10:$A$90,'Master Schedule'!$E$10:$E$90)} -> Wolverines Blue | J36: =ifs(G36=I36,"No_score",G36>I36,F36,I36>G36,H36) -> No_score
A37: 36 | B37: {=XLOOKUP(A37,'Mobile Friendly'!A:A,'Mobile Friendly'!B:B)} -> Masters | C37: Sat | D37: {=XLOOKUP(A37,'Mobile Friendly'!A:A,'Mobile Friendly'!E:E)} -> 1 | E37: {=XLOOKUP(A37,'Mobile Friendly'!A:A,'Mobile Friendly'!C:C)} -> 0.55902778 | F37: {=XLOOKUP(A37,'Master Schedule'!$A$10:$A$90,'Master Schedule'!$C$10:$C$90)} -> Patriot | H37: {=XLOOKUP(A37,'Master Schedule'!$A$10:$A$90,'Master Schedule'!$E$10:$E$90)} -> Team Orlando Black | J37: =ifs(G37=I37,"No_score",G37>I37,F37,I37>G37,H37) -> No_score
A38: 37 | B38: {=XLOOKUP(A38,'Mobile Friendly'!A:A,'Mobile Friendly'!B:B)} -> 18u Girls | C38: Sat | D38: {=XLOOKUP(A38,'Mobile Friendly'!A:A,'Mobile Friendly'!E:E)} -> 2 | E38: {=XLOOKUP(A38,'Mobile Friendly'!A:A,'Mobile Friendly'!C:C)} -> 0.55902778 | F38: {=XLOOKUP(A38,'Master Schedule'!$G$10:$G$90,'Master Schedule'!$I$10:$I$90)} -> Patriot | H38: {=XLOOKUP(A38,'Master Schedule'!$G$10:$G$90,'Master Schedule'!$K$10:$K$90)} -> Orlando Thunder | J38: =ifs(G38=I38,"No_score",G38>I38,F38,I38>G38,H38) -> No_score
A39: 38 | B39: {=XLOOKUP(A39,'Mobile Friendly'!A:A,'Mobile Friendly'!B:B)} -> 12u CoEd | C39: Sat | D39: {=XLOOKUP(A39,'Mobile Friendly'!A:A,'Mobile Friendly'!E:E)} -> 3 | E39: {=XLOOKUP(A39,'Mobile Friendly'!A:A,'Mobile Friendly'!C:C)} -> 0.55902778 | F39: {=XLOOKUP(A39,'Master Schedule'!$A$10:$A$90,'Master Schedule'!$C$10:$C$90)} -> Orlando Thunder | H39: {=XLOOKUP(A39,'Master Schedule'!$A$10:$A$90,'Master Schedule'!$E$10:$E$90)} -> Gladiators | J39: =ifs(G39=I39,"No_score",G39>I39,F39,I39>G39,H39) -> No_score
A40: 39 | B40: {=XLOOKUP(A40,'Mobile Friendly'!A:A,'Mobile Friendly'!B:B)} -> 18u Boys | C40: Sat | D40: {=XLOOKUP(A40,'Mobile Friendly'!A:A,'Mobile Friendly'!E:E)} -> 1 | E40: {=XLOOKUP(A40,'Mobile Friendly'!A:A,'Mobile Friendly'!C:C)} -> 0.59722222 | F40: {=XLOOKUP(A40,'Master Schedule'!$A$10:$A$90,'Master Schedule'!$C$10:$C$90)} -> Gladiators | H40: {=XLOOKUP(A40,'Master Schedule'!$A$10:$A$90,'Master Schedule'!$E$10:$E$90)} -> Blue Dolfins | J40: =ifs(G40=I40,"No_score",G40>I40,F40,I40>G40,H40) -> No_score
...

Sheet TeamBrackets
B1: BRACKETS
G2: Bracket Status
G3: Division | H3: Bracket | I3: Team_Name | J3: Wins | K3: Brk_Rank | L3: Div_Rank
B4: Orlando Thunder | C4: Team Orlando | G4: 10u CoEd | H4: A | I4: Team Orlando | J4: =countifs(Game_Scores!J:J,I4,Game_Scores!B:B,G4) -> 0
B5: Seminole | C5: Kraken | G5: 10u CoEd | H5: A | I5: Orlando Thunder | J5: =countifs(Game_Scores!J:J,I5,Game_Scores!B:B,G5) -> 0
B6: Barcelona | C6: Whitecaps | G6: 12u CoEd | H6: B | I6: Team Orlando | J6: =countifs(Game_Scores!J:J,I6,Game_Scores!B:B,G6) -> 0
B7: Gladiators | C7: Next Level | G7: 12u CoEd | H7: B | I7: Orlando Thunder | J7: =countifs(Game_Scores!J:J,I7,Game_Scores!B:B,G7) -> 0
G8: 12u CoEd | H8: B | I8: Gladiators | J8: =countifs(Game_Scores!J:J,I8,Game_Scores!B:B,G8) -> 0
B9: 18U Girls | G9: 12u CoEd | H9: B | I9: Patriot | J9: =countifs(Game_Scores!J:J,I9,Game_Scores!B:B,G9) -> 0
B10: E | G10: 14u CoEd | H10: C | I10: Team Orlando | J10: =countifs(Game_Scores!J:J,I10,Game_Scores!B:B,G10) -> 0
B11: Seminole | G11: 14u CoEd | H11: C | I11: Wolverines Blue | J11: =countifs(Game_Scores!J:J,I11,Game_Scores!B:B,G11) -> 0
B12: Orlando Thunder | G12: 14u CoEd | H12: C | I12: Patriot | J12: =countifs(Game_Scores!J:J,I12,Game_Scores!B:B,G12) -> 0
B13: Patriot | G13: 14u CoEd | H13: D | I13: Orlando Thunder | J13: =countifs(Game_Scores!J:J,I13,Game_Scores!B:B,G13) -> 0
B14: Team Orlando | G14: 14u CoEd | H14: D | I14: St. Andrews | J14: =countifs(Game_Scores!J:J,I14,Game_Scores!B:B,G14) -> 0
B15: Barcelona | G15: 14u CoEd | H15: D | I15: Orlando United | J15: =countifs(Game_Scores!J:J,I15,Game_Scores!B:B,G15) -> 0
G16: 14u CoEd | H16: E | I16: Seminole | J16: =countifs(Game_Scores!J:J,I16,Game_Scores!B:B,G16) -> 0
B17: 18U Boys | G17: 14u CoEd | H17: E | I17: Gladiators | J17: =countifs(Game_Scores!J:J,I17,Game_Scores!B:B,G17) -> 0
B18: F | C18: G | D18: H | G18: 14u CoEd | H18: E | I18: Wolverines Yellow | J18: =countifs(Game_Scores!J:J,I18,Game_Scores!B:B,G18) -> 0
B19: Barcelona | C19: Hialeah | D19: Thunder Green | G19: 16u Girls | H19: F | I19: Team Orlando | J19: =countifs(Game_Scores!J:J,I19,Game_Scores!B:B,G19) -> 0
B20: Team Orlando | C20: Patriot White | D20: Michigan | G20: 16u Girls | H20: F | I20: Orlando United | J20: =countifs(Game_Scores!J:J,I20,Game_Scores!B:B,G20) -> 0
B21: Patriot Black | C21: Gladiators | D21: Next Level | G21: 16u Girls | H21: F | I21: Orlando Thunder 14 | J21: =countifs(Game_Scores!J:J,I21,Game_Scores!B:B,G21) -> 0
B22: Kraken | C22: Thunder Blue | D22: Team Orlando Black | G22: 16u Girls | H22: G | I22: Orlando Thunder | J22: =countifs(Game_Scores!J:J,I22,Game_Scores!B:B,G22) -> 0
G23: 16u Girls | H23: G | I23: Seminole | J23: =countifs(Game_Scores!J:J,I23,Game_Scores!B:B,G23) -> 0
G24: 16u Girls | H24: G | I24: Patriot | J24: =countifs(Game_Scores!J:J,I24,Game_Scores!B:B,G24) -> 0
G25: 16u Boys | H25: H | I25: Orlando Thunder | J25: =countifs(Game_Scores!J:J,I25,Game_Scores!B:B,G25) -> 0
G26: 16u Boys | H26: H | I26: Gladiators | J26: =countifs(Game_Scores!J:J,I26,Game_Scores!B:B,G26) -> 0
G27: 16u Boys | H27: H | I27: Orlando United | J27: =countifs(Game_Scores!J:J,I27,Game_Scores!B:B,G27) -> 0
G28: 16u Boys | H28: H | I28: Marlins | J28: =countifs(Game_Scores!J:J,I28,Game_Scores!B:B,G28) -> 0
G29: 16u Boys | H29: I | I29: Wolverines | J29: =countifs(Game_Scores!J:J,I29,Game_Scores!B:B,G29) -> 0
G30: 16u Boys | H30: I | I30: Team Orlando | J30: =countifs(Game_Scores!J:J,I30,Game_Scores!B:B,G30) -> 0
G31: 16u Boys | H31: I | I31: Seminole | J31: =countifs(Game_Scores!J:J,I31,Game_Scores!B:B,G31) -> 0
G32: 16u Boys | H32: I | I32: Dynamo | J32: =countifs(Game_Scores!J:J,I32,Game_Scores!B:B,G32) -> 0
G33: 18u Girls | H33: L | I33: Team Orlando | J33: =countifs(Game_Scores!J:J,I33,Game_Scores!B:B,G33) -> 0
G34: 18u Girls | H34: L | I34: Patriot | J34: =countifs(Game_Scores!J:J,I34,Game_Scores!B:B,G34) -> 0
... G49: Masters | H49: P | I49: Team Orlando Black | J49: =countifs(Game_Scores!J:J,I49,Game_Scores!B:B,G49) -> 0

Sheet Fun Stats
A1: ...just some overall numbers from the tournament.
A2: Don't take any of them too seriously.
A4: Division | B4: Dark Pts | C4: Light Pts | D4: Total | E4: No. Games | F4: Avg per Game
A5: 10u CoEd | B5: =round(SUMIFS(Game_Scores!G:G,Game_Scores!B:B,A3),0) -> 0 | C5: =round(SUMIFS(Game_Scores!I:I,Game_Scores!B:B,A5),0) -> 0 | D5: =SUM(B5:C5) -> 0 | E5: =COUNTIFS(Game_Scores!B:B,A5) -> 2 | F5: =D5/E5 -> 0
A6: 12u CoEd | B6: =round(SUMIFS(Game_Scores!G:G,Game_Scores!B:B,A4),0) -> 0 | C6: =round(SUMIFS(Game_Scores!I:I,Game_Scores!B:B,A6),0) -> 0 | D6: =SUM(B6:C6) -> 0 | E6: =COUNTIFS(Game_Scores!B:B,A6) -> 8 | F6: =D6/E6 -> 0
A7: 14u CoEd | B7: =round(SUMIFS(Game_Scores!G:G,Game_Scores!B:B,A2),0) -> 0 | C7: =round(SUMIFS(Game_Scores!I:I,Game_Scores!B:B,A7),0) -> 0 | D7: =SUM(B7:C7) -> 0 | E7: =COUNTIFS(Game_Scores!B:B,A7) -> 18 | F7: =D7/E7 -> 0
A8: 16u Girls | B8: =round(SUMIFS(Game_Scores!G:G,Game_Scores!B:B,A3),0) -> 0 | C8: =round(SUMIFS(Game_Scores!I:I,Game_Scores!B:B,A8),0) -> 0 | D8: =SUM(B8:C8) -> 0 | E8: =COUNTIFS(Game_Scores!B:B,A8) -> 13 | F8: =D8/E8 -> 0
A9: 16u Boys | B9: =round(SUMIFS(Game_Scores!G:G,Game_Scores!B:B,A4),0) -> 0 | C9: =round(SUMIFS(Game_Scores!I:I,Game_Scores!B:B,A9),0) -> 0 | D9: =SUM(B9:C9) -> 0 | E9: =COUNTIFS(Game_Scores!B:B,A9) -> 16 | F9: =D9/E9 -> 0
A10: 18u Girls | B10: =round(SUMIFS(Game_Scores!G:G,Game_Scores!B:B,A5),0) -> 0 | C10: =round(SUMIFS(Game_Scores!I:I,Game_Scores!B:B,A10),0) -> 0 | D10: =SUM(B10:C10) -> 0 | E10: =COUNTIFS(Game_Scores!B:B,A10) -> 3 | F10: =D10/E10 -> 0
A11: 18u Boys | B11: =round(SUMIFS(Game_Scores!G:G,Game_Scores!B:B,A11),0) -> 0 | C11: =round(SUMIFS(Game_Scores!I:I,Game_Scores!B:B,A11),0) -> 0 | D11: =SUM(B11:C11) -> 0 | E11: =COUNTIFS(Game_Scores!B:B,A11) -> 18 | F11: =D11/E11 -> 0
A12: Masters | B12: =round(SUMIFS(Game_Scores!G:G,Game_Scores!B:B,A12),0) -> 0 | C12: =round(SUMIFS(Game_Scores!I:I,Game_Scores!B:B,A12),0) -> 0 | D12: =SUM(B12:C12) -> 0 | E12: =COUNTIFS(Game_Scores!B:B,A12) -> 10 | F12: =D12/E12 -> 0
A15: Pool | B15: Dark Pts | C15: Light Pts | D15: Total Pts | E15: No. Games | F15: Avg per Game
A16: 1 | B16: =round(sumifs(Game_Scores!G:G,Game_Scores!D:D,A16),0) -> 0 | C16: =round(sumifs(Game_Scores!I:I,Game_Scores!D:D,A16),0) -> 0 | D16: =SUM(B16:C16) -> 0 | E16: =COUNTIF(Game_Scores!D:D,A16) -> 31 | F16: =D16/E16 -> 0
A17: 2 | B17: =round(sumifs(Game_Scores!G:G,Game_Scores!D:D,A17),0) -> 0 | C17: =round(sumifs(Game_Scores!I:I,Game_Scores!D:D,A17),0) -> 0 | D17: =SUM(B17:C17) -> 0 | E17: =COUNTIF(Game_Scores!D:D,A17) -> 29 | F17: =D17/E17 -> 0
A18: 3 | B18: =round(sumifs(Game_Scores!G:G,Game_Scores!D:D,A18),0) -> 0 | C18: =round(sumifs(Game_Scores!I:I,Game_Scores!D:D,A18),0) -> 0 | D18: =SUM(B18:C18) -> 0 | E18: =COUNTIF(Game_Scores!D:D,A18) -> 28 | F18: =D18/E18 -> 0
A21: Club | B21: Dark Pts | C21: Light Pts | D21: Total Pts | E21: Num Games | F21: Avg per Game
A22: Blue Dolfins | B22: =round(SUMIFS(Game_Scores!G:G,Game_Scores!F:F,A22),0) -> 0 | C22: =round(sumifs(Game_Scores!I:I,Game_Scores!H:H,A22),0) -> 0 | D22: =SUM(B22:C22) -> 0 | E22: =(countifs(Game_Scores!F:F,A22)+(countifs(Game_Scores!H:H,A22))) -> 2 | F22: =D22/(countifs(Game_Scores!F:F,A22)+(COUNTIFS(Game_Scores!H:H,A22))) -> 0
A23: Dynamo | B23: =round(SUMIFS(Game_Scores!G:G,Game_Scores!F:F,A23),0) -> 0 | C23: =round(sumifs(Game_Scores!I:I,Game_Scores!H:H,A23),0) -> 0 | D23: =SUM(B23:C23) -> 0 | E23: =(countifs(Game_Scores!F:F,A23)+(countifs(Game_Scores!H:H,A23))) -> 3 | F23: =D23/(countifs(Game_Scores!F:F,A23)+(COUNTIFS(Game_Scores!H:H,A23))) -> 0
A24: Gladiators | B24: =round(SUMIFS(Game_Scores!G:G,Game_Scores!F:F,A24),0) -> 0 | C24: =round(sumifs(Game_Scores!I:I,Game_Scores!H:H,A24),0) -> 0 | D24: =SUM(B24:C24) -> 0 | E24: =(countifs(Game_Scores!F:F,A24)+(countifs(Game_Scores!H:H,A24))) -> 10 | F24: =D24/(countifs(Game_Scores!F:F,A24)+(COUNTIFS(Game_Scores!H:H,A24))) -> 0
A25: Marlins | B25: =round(SUMIFS(Game_Scores!G:G,Game_Scores!F:F,A25),0) -> 0 | C25: =round(sumifs(Game_Scores!I:I,Game_Scores!H:H,A25),0) -> 0 | D25: =SUM(B25:C25) -> 0 | E25: =(countifs(Game_Scores!F:F,A25)+(countifs(Game_Scores!H:H,A25))) -> 5 | F25: =D25/(countifs(Game_Scores!F:F,A25)+(COUNTIFS(Game_Scores!H:H,A25))) -> 0
A26: Nextlevel | B26: =round(SUMIFS(Game_Scores!G:G,Game_Scores!F:F,A26),0) -> 0 | C26: =round(sumifs(Game_Scores!I:I,Game_Scores!H:H,A26),0) -> 0 | D26: =SUM(B26:C26) -> 0 | E26: =(countifs(Game_Scores!F:F,A26)+(countifs(Game_Scores!H:H,A26))) -> 2 | F26: =D26/(countifs(Game_Scores!F:F,A26)+(COUNTIFS(Game_Scores!H:H,A26))) -> 0
A27: North Idaho | B27: =round(SUMIFS(Game_Scores!G:G,Game_Scores!F:F,A27),0) -> 0 | C27: =round(sumifs(Game_Scores!I:I,Game_Scores!H:H,A27),0) -> 0 | D27: =SUM(B27:C27) -> 0 | E27: =(countifs(Game_Scores!F:F,A27)+(countifs(Game_Scores!H:H,A27))) -> 2 | F27: =D27/(countifs(Game_Scores!F:F,A27)+(COUNTIFS(Game_Scores!H:H,A27))) -> 0
A28: Orlando Thunder | B28: =round(SUMIFS(Game_Scores!G:G,Game_Scores!F:F,A28),0) -> 0 | C28: =round(sumifs(Game_Scores!I:I,Game_Scores!H:H,A28),0) -> 0 | D28: =SUM(B28:C28) -> 0 | E28: =(countifs(Game_Scores!F:F,A28)+(countifs(Game_Scores!H:H,A28))) -> 20 | F28: =D28/(countifs(Game_Scores!F:F,A28)+(COUNTIFS(Game_Scores!H:H,A28))) -> 0
A29: Orlando Thunder 14 | B29: =round(SUMIFS(Game_Scores!G:G,Game_Scores!F:F,A29),0) -> 0 | C29: =round(sumifs(Game_Scores!I:I,Game_Scores!H:H,A29),0) -> 0 | D29: =SUM(B29:C29) -> 0 | E29: =(countifs(Game_Scores!F:F,A29)+(countifs(Game_Scores!H:H,A29))) -> 2 | F29: =D29/(countifs(Game_Scores!F:F,A29)+(COUNTIFS(Game_Scores!H:H,A29))) -> 0
A30: Orlando United | B30: =round(SUMIFS(Game_Scores!G:G,Game_Scores!F:F,A30),0) -> 0 | C30: =round(sumifs(Game_Scores!I:I,Game_Scores!H:H,A30),0) -> 0 | D30: =SUM(B30:C30) -> 0 | E30: =(countifs(Game_Scores!F:F,A30)+(countifs(Game_Scores!H:H,A30))) -> 9 | F30: =D30/(countifs(Game_Scores!F:F,A30)+(COUNTIFS(Game_Scores!H:H,A30))) -> 0
A31: Patriot | B31: =round(SUMIFS(Game_Scores!G:G,Game_Scores!F:F,A31),0) -> 0 | C31: =round(sumifs(Game_Scores!I:I,Game_Scores!H:H,A31),0) -> 0 | D31: =SUM(B31:C31) -> 0 | E31: =(countifs(Game_Scores!F:F,A31)+(countifs(Game_Scores!H:H,A31))) -> 13 | F31: =D31/(countifs(Game_Scores!F:F,A31)+(COUNTIFS(Game_Scores!H:H,A31))) -> 0
A32: Seminole | B32: =round(SUMIFS(Game_Scores!G:G,Game_Scores!F:F,A32),0) -> 0 | C32: =round(sumifs(Game_Scores!I:I,Game_Scores!H:H,A32),0) -> 0 | D32: =SUM(B32:C32) -> 0 | E32: =(countifs(Game_Scores!F:F,A32)+(countifs(Game_Scores!H:H,A32))) -> 7 | F32: =D32/(countifs(Game_Scores!F:F,A32)+(COUNTIFS(Game_Scores!H:H,A32))) -> 0
A33: St. Andrews | B33: =round(SUMIFS(Game_Scores!G:G,Game_Scores!F:F,A33),0) -> 0 | C33: =round(sumifs(Game_Scores!I:I,Game_Scores!H:H,A33),0) -> 0 | D33: =SUM(B33:C33) -> 0 | E33: =(countifs(Game_Scores!F:F,A33)+(countifs(Game_Scores!H:H,A33))) -> 2 | F33: =D33/(countifs(Game_Scores!F:F,A33)+(COUNTIFS(Game_Scores!H:H,A33))) -> 0
... A39: Wolverines Yellow | B39: =round(SUMIFS(Game_Scores!G:G,Game_Scores!F:F,A39),0) -> 0 | C39: =round(sumifs(Game_Scores!I:I,Game_Scores!H:H,A39),0) -> 0 | D39: =SUM(B39:C39) -> 0 | E39: =(countifs(Game_Scores!F:F,A39)+(countifs(Game_Scores!H:H,A39))) -> 2 | F39: =D39/(countifs(Game_Scores!F:F,A39)+(COUNTIFS(Game_Scores!H:H,A39))) -> 0

Sheet ref_Clubs_Teams
A1: Abb | B1: Age | C1: Club | D1: Bracket
A2: TO | B2: 10U Mixed | C2: Team Orlando | D2: A
A3: THDR | B3: 10U Mixed | C3: Orlando Thunder | D3: A
A4: TO | B4: 12U Mixed | C4: Team Orlando | D4: B
A5: THDR | B5: 12U Mixed | C5: Orlando Thunder | D5: B
A6: GLAD | B6: 12U Mixed | C6: Gladiators | D6: B
A7: PATS | B7: 12U Mixed | C7: Patriot | D7: B
A8: TO | B8: 14U Mixed | C8: Team Orlando | D8: C
A9: WOLVBL | B9: 14U Mixed | C9: Wolverines Blue | D9: C
A10: PATS | B10: 14U Mixed | C10: Patriot | D10: C
A11: THDR | B11: 14U Mixed | C11: Orlando Thunder | D11: D
A12: STAND | B12: 14U Mixed | C12: St. Andrews | D12: D
... A47: TOBLK | B47: Masters | C47: Team Orlando Black | D47: P

Sheet _ref
A1: Team Names | B1: Column 1 | D1: Team Age | F1: Brackets
A2: --- | B2: -- | D2: ---- | F2: A
A3: Blue Dolfins | B3: BLUDOL | D3: 10u CoEd | F3: B
A4: Dynamo | B4: DYNAMO | D4: 12u CoEd | F4: C
A5: Gladiators | B5: GLAD | D5: 14u CoEd | F5: D
A6: Marlins | B6: MARLINS | D6: 16u Girls | F6: E
A7: Nextlevel | B7: NXLV | D7: 16u Boys | F7: F
A8: North Idaho | B8: NARWHAL | D8: 18u Girls | F8: G
A9: Orlando Thunder | B9: THDR | D9: 18u Boys | F9: H
A10: Orlando Thunder 14 | B10: THDR14 | D10: Masters | F10: I
A11: Orlando United | B11: UNIT | F11: J
A12: Patriot | B12: PATS | F12: K
A13: Seminole | B13: NOLES | F13: L
A14: St. Andrews | B14: STAND | F14: M
A15: Tampa | B15: TMPA | F15: N
A16: Team Orlando | B16: TO | F16: O
A17: Team Orlando Black | B17: TOBLK | F17: P
A18: Wolverines | B18: WOLV
A19: Wolverines Blue | B19: WOLVBL
A20: Wolverines Yellow | B20: WOLVYW
A21: 1E
A22: 1B
A23: 1C
A24: 1D
A25: 1E
A26: 1F
A27: 1G
A28: 1H
A29: 1J
A30: 1M
A31: 1N
A32: 1O
... A65: Loser - 54
